Workbook

Sheet Urban_threads_original_data
A1: Order ID | B1: Order Date | C1: Customer ID | D1: Type | E1: SKU | F1: Category | G1: Product Name | H1: Unit Price | I1: Qty | J1: Total | K1: Discount Code | L1: Disc % | M1: Payment | N1: Source | O1: City | P1: State | Q1: Warehouse | R1: Del Date | S1: Status | T1: Return? | U1: Reason | V1: Ret Rec | W1: Refund
A2: UT-100001 | B2: 01-10-2024 | C2: CUST_10001 | D2: New | E2: TOP-CAS-M | F2: Tops | G2: Classic Cotton Tee | H2: 1299 | I2: 2 | J2: 2598 | L2: 0 | M2: UPI | N2: Website | O2: Mumbai | P2: Maharashtra | Q2: Mumbai | R2: 05-10-2024 | S2: Delivered | T2: No | W2: Not Applicable
A3: UT-100002 | B3: 01-10-2024 | C3: CUST_10002 | D3: Returning | E3: DRS-FRM-S | F3: Dresses | G3: Floral Midi Dress | H3: 2499 | I3: 1 | J3: 2499 | K3: DIWALI20 | L3: 20 | M3: Credit Card | N3: Mobile App | O3: Delhi | P3: Delhi | Q3: Delhi | R3: 04-10-2024 | S3: Delivered | T3: Yes | U3: Size Issue | V3: 15-10-2024 | W3: Processed
A4: UT-100003 | B4: 10-01-2024 | C4: CUST_10003 | D4: new | E4: BOT-JNS-L | F4: Bottoms | G4: Slim Fit Jeans | H4: 1899 | I4: 1 | J4: 1899 | L4: 0 | M4: COD | N4: Website | O4: Bangalore | P4: Karnataka | Q4: Bangalore | R4: 06-10-2024 | S4: Delivered | T4: No | W4: Not Applicable
A5: UT-100004 | B5: 01-10-2024 | C5: CUST_10004 | D5: New | E5: OUT-JKT-XL | F5: Outerwear | G5: Denim Jacket | H5: 3499 | I5: 1 | J5: 3499 | K5: FIRST15 | L5: 15 | M5: Debit Card | N5: Instagram Shop | O5: Chennai | P5: Tamil Nadu | Q5: Mumbai | R5: 08-10-2024 | S5: Delivered | T5: Yes | U5: Quality Defect | V5: 20-10-2024 | W5: Processed
A6: UT-100005 | B6: 01-10-2024 | C6: CUST_10001 | D6: New | E6: ACC-SCF-OS | F6: Accessories | G6: Silk Scarf | H6: 799 | I6: 3 | J6: 2397 | L6: 0 | M6: UPI | N6: Website | O6: Mumbai | P6: Maharashtra | Q6: Mumbai | R6: 06-10-2024 | S6: Delivered | T6: No | W6: Not Applicable
A7: UT-100006 | B7: 02-10-2024 | C7: CUST_10005 | D7: Returning | E7: TOP-FRM-S | F7: Tops | G7: Printed Blouse | H7: 1599 | I7: 2 | J7: 3198 | L7: 0 | M7: Credit Card | N7: Mobile App | O7: Hyderabad | P7: Telangana | Q7: Bangalore | R7: 07-10-2024 | S7: Delivered | T7: Yes | U7: Changed Mind | V7: 18-10-2024 | W7: Processed
A8: UT-100007 | B8: 02-10-2024 | C8: CUST_10006 | D8: New | E8: DRS-CAS-M | F8: Dresses | G8: A-Line Dress | H8: 2199 | I8: 1 | J8: 2199 | K8: DIWALI20 | L8: 20 | M8: COD | N8: Website | O8: Pune | P8: Maharashtra | Q8: Mumbai | S8: Cancelled | T8: No | W8: Not Applicable
A9: UT-100008 | B9: 02-10-2024 | C9: CUST_10007 | D9: New | E9: BOT-TRS-L | F9: Bottoms | G9: Formal Trousers | H9: 2299 | I9: 1 | J9: 2299 | L9: 0 | M9: UPI | N9: Mobile App | O9: Kolkata | P9: West Bengal | Q9: Delhi | R9: 10-10-2024 | S9: Delivered | T9: No | W9: Not Applicable
A10: UT-100009 | B10: 02-10-2024 | C10: CUST_10008 | D10: Returning | E10: TOP-CAS-XL | F10: Tops | G10: Oversized Tee | H10: 1399 | I10: 5 | J10: 6995 | L10: 0 | M10: Credit Card | N10: Website | O10: Ahmedabad | P10: Gujarat | Q10: Mumbai | R10: 09-10-2024 | S10: Delivered | T10: Yes | U10: Size Issue | V10: 22-10-2024 | W10: Processed
A11: UT-100010 | B11: 02-10-2024 | C11: CUST_10009 | D11: New | E11: OUT-BLZ-M | F11: Outerwear | G11: Casual Blazer | H11: 4999 | I11: -1 | J11: 4999 | L11: 0 | M11: Debit Card | N11: Instagram Shop | O11: Jaipur | P11: Rajasthan | Q11: Delhi | R11: 11-10-2024 | S11: Delivered | T11: Yes | U11: Wrong Item | V11: 25-10-2024 | W11: Pending
A12: UT-100011 | B12: 03-10-2024 | C12: CUST_10010 | D12: New | E12: ACC-BAG-OS | F12: Accessories | G12: Tote Bag | H12: 1299 | I12: 2 | J12: 2598 | K12: FLAT10 | L12: 10 | M12: Wallet | N12: Website | O12: Lucknow | P12: Uttar Pradesh | Q12: Delhi | R12: 10-10-2024 | S12: Delivered | T12: No | W12: Not Applicable
A13: UT-100012 | B13: 03-10-2024 | C13: CUST_10011 | D13: New | E13: DRS-PRT-S | F13: Dresses | G13: Party Dress | H13: 3299 | I13: 1 | J13: 3299 | L13: 0 | M13: COD | N13: Mobile App | O13: Chandigarh | P13: Punjab | Q13: Delhi | S13: RTO | T13: No | W13: Not Applicable
A14: UT-100013 | B14: 03-10-2024 | C14: CUST_10012 | D14: Returning | E14: TOP-SLK-M | F14: Tops | G14: Silk Blouse | H14: 2499 | I14: 1 | J14: 2499 | L14: 0 | M14: Credit Card | N14: Website | O14: Mumbai | P14: Maharashtra | Q14: Mumbai | R14: 09-10-2024 | S14: Delivered | T14: No | W14: Not Applicable
A15: UT-100014 | B15: 03-10-2024 | C15: CUST_10013 | D15: New | E15: BOT-SKT-S | F15: Bottoms | G15: Pleated Skirt | H15: 1799 | I15: 2 | J15: 3598 | K15: DIWALI20 | L15: 20 | M15: UPI | N15: Instagram Shop | O15: Delhi | P15: Delhi | Q15: Delhi | R15: 11-10-2024 | S15: Delivered | T15: Yes | U15: Size Issue | V15: 28-10-2024 | W15: Processed
A16: UT-100015 | B16: 03-10-2024 | C16: CUST_10014 | D16: New | E16: OUT-CRD-L | F16: Outerwear | G16: Knit Cardigan | H16: 2799 | I16: 1 | J16: 2799 | L16: 0 | M16: Debit Card | N16: Mobile App | O16: Bangalore | P16: Karnataka | Q16: Bangalore | R16: 12-10-2024 | S16: Delivered | T16: No | W16: Not Applicable
A17: UT-100016 | B17: 04-10-2024 | C17: CUST_10015 | D17: Returning | E17: ACC-JWL-OS | F17: Accessories | G17: Statement Earrings | H17: 599 | I17: 4 | J17: 2396 | L17: 0 | M17: COD | N17: Website | O17: Noida | P17: Uttar Pradesh | Q17: Delhi | R17: 14-10-2024 | S17: Delivered | T17: Yes | U17: Damaged in Transit | V17: 26-10-2024 | W17: Processed
A18: UT-100017 | B18: 04-10-2024 | C18: CUST_10016 | D18: New | E18: TOP-CRP-XS | F18: Tops | G18: Crop Top | H18: 999 | I18: 1 | J18: 999 | K18: FIRST15 | L18: 15 | M18: UPI | N18: Mobile App | O18: Gurgaon | P18: Haryana | Q18: Delhi | R18: 12-10-2024 | S18: Delievered | T18: No | W18: Not Applicable
A19: UT-100018 | B19: 04-10-2024 | C19: CUST_10017 | D19: New | E19: DRS-MAX-M | F19: Dresses | G19: Maxi Dress | H19: 2899 | I19: 1 | J19: 2899 | L19: 0 | M19: Credit Card | N19: Website | O19: Indore | P19: Madhya Pradesh | Q19: Mumbai | R19: 14-10-2024 | S19: Delivered | T19: No | W19: Not Applicable
A20: UT-100019 | B20: 04-10-2024 | C20: CUST_10018 | D20: Returning | E20: BOT-JGR-M | F20: Bottoms | G20: Joggers | H20: 1499 | I20: 2 | J20: 2998 | L20: 0 | M20: Wallet | N20: Instagram Shop | O20: Surat | P20: Gujarat | Q20: Mumbai | R20: 13-10-2024 | S20: Delivered | T20: Yes | U20: Size Issue | V20: 30-10-2024 | W20: Processed
A21: UT-100020 | B21: 05-10-2024 | C21: CUST_10019 | D21: New | E21: OUT-VST-S | F21: Outerwear | G21: Puffer Vest | H21: 3999 | I21: 1 | J21: 3999 | K21: DIWALI20 | L21: 20 | M21: COD | N21: Website | O21: Patna | P21: Bihar | Q21: Delhi | S21: RTO | T21: No | W21: Not Applicable
A22: UT-100021 | B22: 05-10-2024 | C22: CUST_10020 | D22: New | E22: TOP-TUN-L | F22: Tops | G22: Tunic Top | H22: 1699 | I22: 1 | J22: 1699 | L22: 0 | M22: UPI | N22: Mobile App | O22: Bhopal | P22: Madhya Pradesh | Q22: Mumbai | R22: 15-10-2024 | S22: Delivered | T22: No | W22: Not Applicable
A23: UT-100022 | B23: 05-10-2024 | C23: CUST_10021 | D23: Returning | E23: DRS-SHT-XS | F23: Dresses | G23: Shirt Dress | H23: 2399 | I23: 1 | J23: 2399 | L23: 0 | M23: Credit Card | N23: Website | O23: Nagpur | P23: Maharashtra | Q23: Mumbai | R23: 16-10-2024 | S23: Delivered | T23: Yes | U23: Quality Defect | V23: 02-11-2024 | W23: Processed
A24: UT-100023 | B24: 05-10-2024 | C24: CUST_10022 | D24: New | E24: ACC-BLT-M | F24: Accessories | G24: Leather Belt | H24: 899 | I24: 1 | J24: 899 | K24: FLAT10 | L24: 10 | M24: Debit Card | N24: Mobile App | O24: Coimbatore | P24: Tamil Nadu | Q24: Bangalore | R24: 17-10-2024 | S24: Delivered | T24: No | W24: Not Applicable
A25: UT-100024 | B25: 06-10-2024 | C25: CUST_10023 | D25: New | E25: BOT-SHT-M | F25: Bottoms | G25: Cotton Shorts | H25: 1199 | I25: 3 | J25: 3597 | L25: 0 | M25: COD | N25: Instagram Shop | O25: Kochi | P25: Kerala | Q25: Bangalore | R25: 18-10-2024 | S25: Delivered | T25: Yes | U25: Changed Mind | V25: 05-11-2024 | W25: Processed
A26: UT-100025 | B26: 06-10-2024 | C26: CUST_10024 | D26: New | E26: TOP-PLO-L | F26: Tops | G26: Polo Shirt | H26: 1799 | I26: 2 | J26: 3598 | L26: 0 | M26: UPI | N26: Website | O26: Vizag | P26: Andhra Pradesh | Q26: Bangalore | R26: 17-10-2024 | S26: Delivered | T26: No | W26: Not Applicable
A27: UT-100026 | B27: 06-10-2024 | C27: CUST_10025 | D27: New | E27: DRS-WRK-M | F27: Dresses | G27: Work Dress | H27: 2699 | I27: 1 | J27: 2699 | L27: 0 | M27: Credit Card | N27: Mobile App | O27: Thiruvananthapuram | P27: Kerala | Q27: Bangalore | R27: 18-10-2024 | S27: Delivered | T27: No | W27: Not Applicable
A28: UT-100027 | B28: 06-10-2024 | C28: CUST_10026 | D28: Returning | E28: OUT-TRN-L | F28: Outerwear | G28: Trench Coat | H28: 4599 | I28: 1 | J28: 4599 | K28: FLAT10 | L28: 10 | M28: Debit Card | N28: Website | O28: Mysore | P28: Karnataka | Q28: Bangalore | R28: 19-10-2024 | S28: Delivered | T28: Yes | U28: Size Issue | V28: 08-11-2024 | W28: Processed
A29: UT-100028 | B29: 07-10-2024 | C29: CUST_10027 | D29: New | E29: ACC-HAT-OS | F29: Accessories | G29: Fedora Hat | H29: 1099 | I29: 1 | J29: 1099 | L29: 0 | M29: UPI | N29: Instagram Shop | O29: Vadodara | P29: Gujarat | Q29: Mumbai | R29: 20-10-2024 | S29: Delivered | T29: No | W29: Not Applicable
A30: UT-100029 | B30: 07-10-2024 | C30: CUST_10028 | D30: New | E30: TOP-DNM-M | F30: Tops | G30: Denim Shirt | H30: 1899 | I30: 1 | J30: 1899 | L30: 0 | M30: COD | N30: Mobile App | O30: Rajkot | P30: Gujarat | Q30: Mumbai | S30: RTO | T30: No | W30: Not Applicable
A31: UT-100030 | B31: 07-10-2024 | C31: CUST_10029 | D31: New | E31: BOT-CRG-L | F31: Bottoms | G31: Cargo Pants | H31: 2199 | I31: 1 | J31: 2199 | K31: DIWALI20 | L31: 20 | M31: Credit Card | N31: Website | O31: Kanpur | P31: Uttar Pradesh | Q31: Delhi | R31: 20-10-2024 | S31: Delivered | T31: No | W31: Not Applicable
A32: UT-100031 | B32: 07-10-2024 | C32: CUST_10030 | D32: Returning | E32: DRS-EVE-S | F32: Dresses | G32: Evening Gown | H32: 5499 | I32: 1 | J32: 5499 | L32: 0 | M32: Credit Card | N32: Mobile App | O32: Mumbai | P32: Maharashtra | Q32: Mumbai | R32: 21-10-2024 | S32: Delivered | T32: Yes | U32: Size Issue | V32: 10-11-2024 | W32: Processed
A33: UT-100032 | B33: 08-10-2024 | C33: CUST_10031 | D33: New | E33: TOP-BAS-M | F33: Tops | G33: Basic Tank | H33: 899 | I33: 2 | J33: 1798 | L33: 0 | M33: UPI | N33: Website | O33: Delhi | P33: Delhi | Q33: Delhi | R33: 14-10-2024 | S33: Delivered | T33: No | W33: Not Applicable
A34: UT-100033 | B34: 08-10-2024 | C34: CUST_10032 | D34: New | E34: OUT-WOL-L | F34: Outerwear | G34: Wool Coat | H34: 6999 | I34: 1 | J34: 6999 | K34: FIRST15 | L34: 15 | M34: Debit Card | N34: Instagram Shop | O34: Kolkata | P34: West Bengal | Q34: Delhi | R34: 16-10-2024 | S34: Delivered | T34: Yes | U34: Quality Defect | V34: 05-11-2024 | W34: Processed
A35: UT-100034 | B35: 08-10-2024 | C35: CUST_10033 | D35: Returning | E35: ACC-WCH-OS | F35: Accessories | G35: Fashion Watch | H35: 2999 | I35: 1 | J35: 2999 | L35: 0 | M35: Credit Card | N35: Mobile App | O35: Chennai | P35: Tamil Nadu | Q35: Bangalore | R35: 15-10-2024 | S35: Delivered | T35: No | W35: Not Applicable
A36: UT-100035 | B36: 08-10-2024 | C36: CUST_10034 | D36: New | E36: BOT-DNM-S | F36: Bottoms | G36: Denim Shorts | H36: 1599 | I36: 1 | J36: 1599 | L36: 0 | M36: COD | N36: Website | O36: Hyderabad | P36: Telangana | Q36: Bangalore | R36: 17-10-2024 | S36: Delivered | T36: Yes | U36: Size Issue | V36: 08-11-2024 | W36: Processed
A37: UT-100036 | B37: 09-10-2024 | C37: CUST_10035 | D37: New | E37: DRS-SUN-M | F37: Dresses | G37: Sundress | H37: 1999 | I37: 1 | J37: 1999 | K37: DIWALI20 | L37: 20 | M37: Wallet | N37: Mobile App | O37: Pune | P37: Maharashtra | Q37: Mumbai | R37: 16-10-2024 | S37: Delivered | T37: No | W37: Not Applicable
A38: UT-100037 | B38: 09-10-2024 | C38: CUST_10036 | D38: New | E38: TOP-RFL-S | F38: Tops | G38: Ruffle Top | H38: 1799 | I38: 1 | J38: 1799 | L38: 0 | M38: UPI | N38: Instagram Shop | O38: Ahmedabad | P38: Gujarat | Q38: Mumbai | R38: 17-10-2024 | S38: Delivered | T38: Yes | U38: Changed Mind | V38: 12-11-2024 | W38: Processed
A39: UT-100038 | B39: 09-10-2024 | C39: CUST_10037 | D39: Returning | E39: OUT-LTH-M | F39: Outerwear | G39: Leather Jacket | H39: 7999 | I39: 1 | J39: 7999 | L39: 0 | M39: Credit Card | N39: Website | O39: Jaipur | P39: Rajasthan | Q39: Delhi | R39: 18-10-2024 | S39: Delivered | T39: No | W39: Not Applicable
A40: UT-100039 | B40: 09-10-2024 | C40: CUST_10038 | D40: New | E40: ACC-SNG-OS | F40: Accessories | G40: Sunglasses | H40: 1499 | I40: 1 | J40: 1499 | K40: FLAT10 | L40: 10 | M40: Debit Card | N40: Mobile App | O40: Lucknow | P40: Uttar Pradesh | Q40: Delhi | R40: 17-10-2024 | S40: Delivered | T40: No | W40: Not Applicable
...

Sheet Validated_Raw_Data
A1: Order ID | B1: Order Date | C1: Order_Date_Validation_Q4 | D1: Customer ID | E1: Type | F1: Product_SKU | G1: Category | H1: Product Name | I1: Unit Price | J1: Qty | K1: Order_Quantity_Validation | L1: Total | M1: Order_Total_After_Discount | N1: Discount Code | O1: Disc % | P1: Discount_Amount | Q1: Payment | R1: Source | S1: City | T1: State | U1: Warehouse | V1: Delivery Date | W1: Delivery_Date_Validation | X1: Delivery_Time_Validation | Y1: Status | Z1: Return? | AA1: Reason | AB1: Return Received | AC1: Return_Date_Validation | AD1: Return_Window_Validation | AE1: Refund
A2: UT-100001 | B2: 45566 | C2: Valid Q4 | D2: CUST_10001 | E2: New | F2: TOP-CAS-M | G2: Tops | H2: Classic Cotton Tee | I2: 1299 | J2: 2 | K2: Valid Quantity | L2: 2598 | M2: 2598 | O2: 0 | P2: 0 | Q2: UPI | R2: Website | S2: Mumbai | T2: Maharashtra | U2: Mumbai | V2: 45570 | W2: Valid Date | X2: On time delivery | Y2: Delivered | Z2: No | AC2: Not Returned | AD2: Not returned | AE2: Not Applicable
A3: UT-100002 | B3: 45566 | C3: Valid Q4 | D3: CUST_10002 | E3: Returning | F3: DRS-FRM-S | G3: Dresses | H3: Floral Midi Dress | I3: 2499 | J3: 1 | K3: Valid Quantity | L3: 2499 | M3: 1999.2 | N3: DIWALI20 | O3: 20 | P3: 499.8 | Q3: Credit Card | R3: Mobile App | S3: Delhi | T3: Delhi | U3: Delhi | V3: 45569 | W3: Valid Date | X3: On time delivery | Y3: Delivered | Z3: Yes | AA3: Size Issue | AB3: 45580 | AC3: Returned | AD3: Valid | AE3: Processed
A4: UT-100003 | B4: 45301 | C4: Out of Q4 | D4: CUST_10003 | E4: New | F4: BOT-JNS-L | G4: Bottoms | H4: Slim Fit Jeans | I4: 1899 | J4: 1 | K4: Valid Quantity | L4: 1899 | M4: 1899 | O4: 0 | P4: 0 | Q4: COD | R4: Website | S4: Bangalore | T4: Karnataka | U4: Bangalore | V4: 45571 | W4: Valid Date | X4: Late delivery | Y4: Delivered | Z4: No | AC4: Not Returned | AD4: Not returned | AE4: Not Applicable
A5: UT-100004 | B5: 45566 | C5: Valid Q4 | D5: CUST_10004 | E5: New | F5: OUT-JKT-XL | G5: Outerwear | H5: Denim Jacket | I5: 3499 | J5: 1 | K5: Valid Quantity | L5: 3499 | M5: 2974.15 | N5: FIRST15 | O5: 15 | P5: 524.85 | Q5: Debit Card | R5: Instagram Shop | S5: Chennai | T5: Tamil Nadu | U5: Mumbai | V5: 45573 | W5: Valid Date | X5: On time delivery | Y5: Delivered | Z5: Yes | AA5: Quality Defect | AB5: 45585 | AC5: Returned | AD5: Valid | AE5: Processed
A6: UT-100005 | B6: 45566 | C6: Valid Q4 | D6: CUST_10001 | E6: New | F6: ACC-SCF-OS | G6: Accessories | H6: Silk Scarf | I6: 799 | J6: 3 | K6: Valid Quantity | L6: 2397 | M6: 2397 | O6: 0 | P6: 0 | Q6: UPI | R6: Website | S6: Mumbai | T6: Maharashtra | U6: Mumbai | V6: 45571 | W6: Valid Date | X6: On time delivery | Y6: Delivered | Z6: No | AC6: Not Returned | AD6: Not returned | AE6: Not Applicable
A7: UT-100006 | B7: 45567 | C7: Valid Q4 | D7: CUST_10005 | E7: Returning | F7: TOP-FRM-S | G7: Tops | H7: Printed Blouse | I7: 1599 | J7: 2 | K7: Valid Quantity | L7: 3198 | M7: 3198 | O7: 0 | P7: 0 | Q7: Credit Card | R7: Mobile App | S7: Hyderabad | T7: Telangana | U7: Bangalore | V7: 45572 | W7: Valid Date | X7: On time delivery | Y7: Delivered | Z7: Yes | AA7: Changed Mind | AB7: 45583 | AC7: Returned | AD7: Valid | AE7: Processed
A8: UT-100007 | B8: 45567 | C8: Valid Q4 | D8: CUST_10006 | E8: New | F8: DRS-CAS-M | G8: Dresses | H8: A-Line Dress | I8: 2199 | J8: 1 | K8: Valid Quantity | L8: 2199 | M8: 1759.2 | N8: DIWALI20 | O8: 20 | P8: 439.8 | Q8: COD | R8: Website | S8: Pune | T8: Maharashtra | U8: Mumbai | W8: Not Delivered | X8: Not delivered | Y8: Cancelled | Z8: No | AC8: Not Delivered | AD8: Not returned | AE8: Not Applicable
A9: UT-100008 | B9: 45567 | C9: Valid Q4 | D9: CUST_10007 | E9: New | F9: BOT-TRS-L | G9: Bottoms | H9: Formal Trousers | I9: 2299 | J9: 1 | K9: Valid Quantity | L9: 2299 | M9: 2299 | O9: 0 | P9: 0 | Q9: UPI | R9: Mobile App | S9: Kolkata | T9: West Bengal | U9: Delhi | V9: 45575 | W9: Valid Date | X9: On time delivery | Y9: Delivered | Z9: No | AC9: Not Returned | AD9: Not returned | AE9: Not Applicable
A10: UT-100009 | B10: 45567 | C10: Valid Q4 | D10: CUST_10008 | E10: Returning | F10: TOP-CAS-XL | G10: Tops | H10: Oversized Tee | I10: 1399 | J10: 5 | K10: Valid Quantity | L10: 6995 | M10: 6995 | O10: 0 | P10: 0 | Q10: Credit Card | R10: Website | S10: Ahmedabad | T10: Gujarat | U10: Mumbai | V10: 45574 | W10: Valid Date | X10: On time delivery | Y10: Delivered | Z10: Yes | AA10: Size Issue | AB10: 45587 | AC10: Returned | AD10: Valid | AE10: Processed
A11: UT-100010 | B11: 45567 | C11: Valid Q4 | D11: CUST_10009 | E11: New | F11: OUT-BLZ-M | G11: Outerwear | H11: Casual Blazer | I11: 4999 | J11: -1 | K11: Invalid Quantity | L11: 4999 | M11: -4999 | O11: 0 | P11: 0 | Q11: Debit Card | R11: Instagram Shop | S11: Jaipur | T11: Rajasthan | U11: Delhi | V11: 45576 | W11: Valid Date | X11: On time delivery | Y11: Delivered | Z11: Yes | AA11: Wrong Item | AB11: 45590 | AC11: Returned | AD11: Valid | AE11: Pending
A12: UT-100011 | B12: 45568 | C12: Valid Q4 | D12: CUST_10010 | E12: New | F12: ACC-BAG-OS | G12: Accessories | H12: Tote Bag | I12: 1299 | J12: 2 | K12: Valid Quantity | L12: 2598 | M12: 2338.2 | N12: FLAT10 | O12: 10 | P12: 259.8 | Q12: Wallet | R12: Website | S12: Lucknow | T12: Uttar Pradesh | U12: Delhi | V12: 45575 | W12: Valid Date | X12: On time delivery | Y12: Delivered | Z12: No | AC12: Not Returned | AD12: Not returned | AE12: Not Applicable
A13: UT-100012 | B13: 45568 | C13: Valid Q4 | D13: CUST_10011 | E13: New | F13: DRS-PRT-S | G13: Dresses | H13: Party Dress | I13: 3299 | J13: 1 | K13: Valid Quantity | L13: 3299 | M13: 3299 | O13: 0 | P13: 0 | Q13: COD | R13: Mobile App | S13: Chandigarh | T13: Punjab | U13: Delhi | W13: Not Delivered | X13: Not delivered | Y13: RTO | Z13: No | AC13: Not Delivered | AD13: Not returned | AE13: Not Applicable
A14: UT-100013 | B14: 45568 | C14: Valid Q4 | D14: CUST_10012 | E14: Returning | F14: TOP-SLK-M | G14: Tops | H14: Silk Blouse | I14: 2499 | J14: 1 | K14: Valid Quantity | L14: 2499 | M14: 2499 | O14: 0 | P14: 0 | Q14: Credit Card | R14: Website | S14: Mumbai | T14: Maharashtra | U14: Mumbai | V14: 45574 | W14: Valid Date | X14: On time delivery | Y14: Delivered | Z14: No | AC14: Not Returned | AD14: Not returned | AE14: Not Applicable
A15: UT-100014 | B15: 45568 | C15: Valid Q4 | D15: CUST_10013 | E15: New | F15: BOT-SKT-S | G15: Bottoms | H15: Pleated Skirt | I15: 1799 | J15: 2 | K15: Valid Quantity | L15: 3598 | M15: 2878.4 | N15: DIWALI20 | O15: 20 | P15: 719.6 | Q15: UPI | R15: Instagram Shop | S15: Delhi | T15: Delhi | U15: Delhi | V15: 45576 | W15: Valid Date | X15: On time delivery | Y15: Delivered | Z15: Yes | AA15: Size Issue | AB15: 45593 | AC15: Returned | AD15: Valid | AE15: Processed
A16: UT-100015 | B16: 45568 | C16: Valid Q4 | D16: CUST_10014 | E16: New | F16: OUT-CRD-L | G16: Outerwear | H16: Knit Cardigan | I16: 2799 | J16: 1 | K16: Valid Quantity | L16: 2799 | M16: 2799 | O16: 0 | P16: 0 | Q16: Debit Card | R16: Mobile App | S16: Bangalore | T16: Karnataka | U16: Bangalore | V16: 45577 | W16: Valid Date | X16: On time delivery | Y16: Delivered | Z16: No | AC16: Not Returned | AD16: Not returned | AE16: Not Applicable
A17: UT-100016 | B17: 45569 | C17: Valid Q4 | D17: CUST_10015 | E17: Returning | F17: ACC-JWL-OS | G17: Accessories | H17: Statement Earrings | I17: 599 | J17: 4 | K17: Valid Quantity | L17: 2396 | M17: 2396 | O17: 0 | P17: 0 | Q17: COD | R17: Website | S17: Noida | T17: Uttar Pradesh | U17: Delhi | V17: 45579 | W17: Valid Date | X17: On time delivery | Y17: Delivered | Z17: Yes | AA17: Damaged in Transit | AB17: 45591 | AC17: Returned | AD17: Valid | AE17: Processed
A18: UT-100017 | B18: 45569 | C18: Valid Q4 | D18: CUST_10016 | E18: New | F18: TOP-CRP-XS | G18: Tops | H18: Crop Top | I18: 999 | J18: 1 | K18: Valid Quantity | L18: 999 | M18: 849.15 | N18: FIRST15 | O18: 15 | P18: 149.85 | Q18: UPI | R18: Mobile App | S18: Gurgaon | T18: Haryana | U18: Delhi | V18: 45577 | W18: Valid Date | X18: On time delivery | Y18: Delivered | Z18: No | AC18: Not Returned | AD18: Not returned | AE18: Not Applicable
A19: UT-100018 | B19: 45569 | C19: Valid Q4 | D19: CUST_10017 | E19: New | F19: DRS-MAX-M | G19: Dresses | H19: Maxi Dress | I19: 2899 | J19: 1 | K19: Valid Quantity | L19: 2899 | M19: 2899 | O19: 0 | P19: 0 | Q19: Credit Card | R19: Website | S19: Indore | T19: Madhya Pradesh | U19: Mumbai | V19: 45579 | W19: Valid Date | X19: On time delivery | Y19: Delivered | Z19: No | AC19: Not Returned | AD19: Not returned | AE19: Not Applicable
A20: UT-100019 | B20: 45569 | C20: Valid Q4 | D20: CUST_10018 | E20: Returning | F20: BOT-JGR-M | G20: Bottoms | H20: Joggers | I20: 1499 | J20: 2 | K20: Valid Quantity | L20: 2998 | M20: 2998 | O20: 0 | P20: 0 | Q20: Wallet | R20: Instagram Shop | S20: Surat | T20: Gujarat | U20: Mumbai | V20: 45578 | W20: Valid Date | X20: On time delivery | Y20: Delivered | Z20: Yes | AA20: Size Issue | AB20: 45595 | AC20: Returned | AD20: Valid | AE20: Processed
A21: UT-100020 | B21: 45570 | C21: Valid Q4 | D21: CUST_10019 | E21: New | F21: OUT-VST-S | G21: Outerwear | H21: Puffer Vest | I21: 3999 | J21: 1 | K21: Valid Quantity | L21: 3999 | M21: 3199.2 | N21: DIWALI20 | O21: 20 | P21: 799.8 | Q21: COD | R21: Website | S21: Patna | T21: Bihar | U21: Delhi | W21: Not Delivered | X21: Not delivered | Y21: RTO | Z21: No | AC21: Not Delivered | AD21: Not returned | AE21: Not Applicable
A22: UT-100021 | B22: 45570 | C22: Valid Q4 | D22: CUST_10020 | E22: New | F22: TOP-TUN-L | G22: Tops | H22: Tunic Top | I22: 1699 | J22: 1 | K22: Valid Quantity | L22: 1699 | M22: 1699 | O22: 0 | P22: 0 | Q22: UPI | R22: Mobile App | S22: Bhopal | T22: Madhya Pradesh | U22: Mumbai | V22: 45580 | W22: Valid Date | X22: On time delivery | Y22: Delivered | Z22: No | AC22: Not Returned | AD22: Not returned | AE22: Not Applicable
A23: UT-100022 | B23: 45570 | C23: Valid Q4 | D23: CUST_10021 | E23: Returning | F23: DRS-SHT-XS | G23: Dresses | H23: Shirt Dress | I23: 2399 | J23: 1 | K23: Valid Quantity | L23: 2399 | M23: 2399 | O23: 0 | P23: 0 | Q23: Credit Card | R23: Website | S23: Nagpur | T23: Maharashtra | U23: Mumbai | V23: 45581 | W23: Valid Date | X23: On time delivery | Y23: Delivered | Z23: Yes | AA23: Quality Defect | AB23: 45598 | AC23: Returned | AD23: Valid | AE23: Processed
A24: UT-100023 | B24: 45570 | C24: Valid Q4 | D24: CUST_10022 | E24: New | F24: ACC-BLT-M | G24: Accessories | H24: Leather Belt | I24: 899 | J24: 1 | K24: Valid Quantity | L24: 899 | M24: 809.1 | N24: FLAT10 | O24: 10 | P24: 89.9 | Q24: Debit Card | R24: Mobile App | S24: Coimbatore | T24: Tamil Nadu | U24: Bangalore | V24: 45582 | W24: Valid Date | X24: On time delivery | Y24: Delivered | Z24: No | AC24: Not Returned | AD24: Not returned | AE24: Not Applicable
A25: UT-100024 | B25: 45571 | C25: Valid Q4 | D25: CUST_10023 | E25: New | F25: BOT-SHT-M | G25: Bottoms | H25: Cotton Shorts | I25: 1199 | J25: 3 | K25: Valid Quantity | L25: 3597 | M25: 3597 | O25: 0 | P25: 0 | Q25: COD | R25: Instagram Shop | S25: Kochi | T25: Kerala | U25: Bangalore | V25: 45583 | W25: Valid Date | X25: On time delivery | Y25: Delivered | Z25: Yes | AA25: Changed Mind | AB25: 45601 | AC25: Returned | AD25: Valid | AE25: Processed
A26: UT-100025 | B26: 45571 | C26: Valid Q4 | D26: CUST_10024 | E26: New | F26: TOP-PLO-L | G26: Tops | H26: Polo Shirt | I26: 1799 | J26: 2 | K26: Valid Quantity | L26: 3598 | M26: 3598 | O26: 0 | P26: 0 | Q26: UPI | R26: Website | S26: Vizag | T26: Andhra Pradesh | U26: Bangalore | V26: 45582 | W26: Valid Date | X26: On time delivery | Y26: Delivered | Z26: No | AC26: Not Returned | AD26: Not returned | AE26: Not Applicable
A27: UT-100026 | B27: 45571 | C27: Valid Q4 | D27: CUST_10025 | E27: New | F27: DRS-WRK-M | G27: Dresses | H27: Work Dress | I27: 2699 | J27: 1 | K27: Valid Quantity | L27: 2699 | M27: 2699 | O27: 0 | P27: 0 | Q27: Credit Card | R27: Mobile App | S27: Thiruvananthapuram | T27: Kerala | U27: Bangalore | V27: 45583 | W27: Valid Date | X27: On time delivery | Y27: Delivered | Z27: No | AC27: Not Returned | AD27: Not returned | AE27: Not Applicable
A28: UT-100027 | B28: 45571 | C28: Valid Q4 | D28: CUST_10026 | E28: Returning | F28: OUT-TRN-L | G28: Outerwear | H28: Trench Coat | I28: 4599 | J28: 1 | K28: Valid Quantity | L28: 4599 | M28: 4139.1 | N28: FLAT10 | O28: 10 | P28: 459.9 | Q28: Debit Card | R28: Website | S28: Mysore | T28: Karnataka | U28: Bangalore | V28: 45584 | W28: Valid Date | X28: On time delivery | Y28: Delivered | Z28: Yes | AA28: Size Issue | AB28: 45604 | AC28: Returned | AD28: Valid | AE28: Processed
A29: UT-100028 | B29: 45572 | C29: Valid Q4 | D29: CUST_10027 | E29: New | F29: ACC-HAT-OS | G29: Accessories | H29: Fedora Hat | I29: 1099 | J29: 1 | K29: Valid Quantity | L29: 1099 | M29: 1099 | O29: 0 | P29: 0 | Q29: UPI | R29: Instagram Shop | S29: Vadodara | T29: Gujarat | U29: Mumbai | V29: 45585 | W29: Valid Date | X29: On time delivery | Y29: Delivered | Z29: No | AC29: Not Returned | AD29: Not returned | AE29: Not Applicable
A30: UT-100029 | B30: 45572 | C30: Valid Q4 | D30: CUST_10028 | E30: New | F30: TOP-DNM-M | G30: Tops | H30: Denim Shirt | I30: 1899 | J30: 1 | K30: Valid Quantity | L30: 1899 | M30: 1899 | O30: 0 | P30: 0 | Q30: COD | R30: Mobile App | S30: Rajkot | T30: Gujarat | U30: Mumbai | W30: Not Delivered | X30: Not delivered | Y30: RTO | Z30: No | AC30: Not Delivered | AD30: Not returned | AE30: Not Applicable
A31: UT-100030 | B31: 45572 | C31: Valid Q4 | D31: CUST_10029 | E31: New | F31: BOT-CRG-L | G31: Bottoms | H31: Cargo Pants | I31: 2199 | J31: 1 | K31: Valid Quantity | L31: 2199 | M31: 1759.2 | N31: DIWALI20 | O31: 20 | P31: 439.8 | Q31: Credit Card | R31: Website | S31: Kanpur | T31: Uttar Pradesh | U31: Delhi | V31: 45585 | W31: Valid Date | X31: On time delivery | Y31: Delivered | Z31: No | AC31: Not Returned | AD31: Not returned | AE31: Not Applicable
A32: UT-100031 | B32: 45572 | C32: Valid Q4 | D32: CUST_10030 | E32: Returning | F32: DRS-EVE-S | G32: Dresses | H32: Evening Gown | I32: 5499 | J32: 1 | K32: Valid Quantity | L32: 5499 | M32: 5499 | O32: 0 | P32: 0 | Q32: Credit Card | R32: Mobile App | S32: Mumbai | T32: Maharashtra | U32: Mumbai | V32: 45586 | W32: Valid Date | X32: On time delivery | Y32: Delivered | Z32: Yes | AA32: Size Issue | AB32: 45606 | AC32: Returned | AD32: Valid | AE32: Processed
A33: UT-100032 | B33: 45573 | C33: Valid Q4 | D33: CUST_10031 | E33: New | F33: TOP-BAS-M | G33: Tops | H33: Basic Tank | I33: 899 | J33: 2 | K33: Valid Quantity | L33: 1798 | M33: 1798 | O33: 0 | P33: 0 | Q33: UPI | R33: Website | S33: Delhi | T33: Delhi | U33: Delhi | V33: 45579 | W33: Valid Date | X33: On time delivery | Y33: Delivered | Z33: No | AC33: Not Returned | AD33: Not returned | AE33: Not Applicable
A34: UT-100033 | B34: 45573 | C34: Valid Q4 | D34: CUST_10032 | E34: New | F34: OUT-WOL-L | G34: Outerwear | H34: Wool Coat | I34: 6999 | J34: 1 | K34: Valid Quantity | L34: 6999 | M34: 5949.15 | N34: FIRST15 | O34: 15 | P34: 1049.85 | Q34: Debit Card | R34: Instagram Shop | S34: Kolkata | T34: West Bengal | U34: Delhi | V34: 45581 | W34: Valid Date | X34: On time delivery | Y34: Delivered | Z34: Yes | AA34: Quality Defect | AB34: 45601 | AC34: Returned | AD34: Valid | AE34: Processed
A35: UT-100034 | B35: 45573 | C35: Valid Q4 | D35: CUST_10033 | E35: Returning | F35: ACC-WCH-OS | G35: Accessories | H35: Fashion Watch | I35: 2999 | J35: 1 | K35: Valid Quantity | L35: 2999 | M35: 2999 | O35: 0 | P35: 0 | Q35: Credit Card | R35: Mobile App | S35: Chennai | T35: Tamil Nadu | U35: Bangalore | V35: 45580 | W35: Valid Date | X35: On time delivery | Y35: Delivered | Z35: No | AC35: Not Returned | AD35: Not returned | AE35: Not Applicable
A36: UT-100035 | B36: 45573 | C36: Valid Q4 | D36: CUST_10034 | E36: New | F36: BOT-DNM-S | G36: Bottoms | H36: Denim Shorts | I36: 1599 | J36: 1 | K36: Valid Quantity | L36: 1599 | M36: 1599 | O36: 0 | P36: 0 | Q36: COD | R36: Website | S36: Hyderabad | T36: Telangana | U36: Bangalore | V36: 45582 | W36: Valid Date | X36: On time delivery | Y36: Delivered | Z36: Yes | AA36: Size Issue | AB36: 45604 | AC36: Returned | AD36: Valid | AE36: Processed
A37: UT-100036 | B37: 45574 | C37: Valid Q4 | D37: CUST_10035 | E37: New | F37: DRS-SUN-M | G37: Dresses | H37: Sundress | I37: 1999 | J37: 1 | K37: Valid Quantity | L37: 1999 | M37: 1599.2 | N37: DIWALI20 | O37: 20 | P37: 399.8 | Q37: Wallet | R37: Mobile App | S37: Pune | T37: Maharashtra | U37: Mumbai | V37: 45581 | W37: Valid Date | X37: On time delivery | Y37: Delivered | Z37: No | AC37: Not Returned | AD37: Not returned | AE37: Not Applicable
A38: UT-100037 | B38: 45574 | C38: Valid Q4 | D38: CUST_10036 | E38: New | F38: TOP-RFL-S | G38: Tops | H38: Ruffle Top | I38: 1799 | J38: 1 | K38: Valid Quantity | L38: 1799 | M38: 1799 | O38: 0 | P38: 0 | Q38: UPI | R38: Instagram Shop | S38: Ahmedabad | T38: Gujarat | U38: Mumbai | V38: 45582 | W38: Valid Date | X38: On time delivery | Y38: Delivered | Z38: Yes | AA38: Changed Mind | AB38: 45608 | AC38: Returned | AD38: Valid | AE38: Processed
A39: UT-100038 | B39: 45574 | C39: Valid Q4 | D39: CUST_10037 | E39: Returning | F39: OUT-LTH-M | G39: Outerwear | H39: Leather Jacket | I39: 7999 | J39: 1 | K39: Valid Quantity | L39: 7999 | M39: 7999 | O39: 0 | P39: 0 | Q39: Credit Card | R39: Website | S39: Jaipur | T39: Rajasthan | U39: Delhi | V39: 45583 | W39: Valid Date | X39: On time delivery | Y39: Delivered | Z39: No | AC39: Not Returned | AD39: Not returned | AE39: Not Applicable
A40: UT-100039 | B40: 45574 | C40: Valid Q4 | D40: CUST_10038 | E40: New | F40: ACC-SNG-OS | G40: Accessories | H40: Sunglasses | I40: 1499 | J40: 1 | K40: Valid Quantity | L40: 1499 | M40: 1349.1 | N40: FLAT10 | O40: 10 | P40: 149.9 | Q40: Debit Card | R40: Mobile App | S40: Lucknow | T40: Uttar Pradesh | U40: Delhi | V40: 45582 | W40: Valid Date | X40: On time delivery | Y40: Delivered | Z40: No | AC40: Not Returned | AD40: Not returned | AE40: Not Applicable
...

Sheet Cleaned_Data
A1: Order ID | B1: Order Date | C1: Order_Date_Validation_Q4 | D1: Customer ID | E1: Type | F1: Product_SKU | G1: Category | H1: Product Name | I1: Unit Price | J1: Qty | K1: Order_Quantity_Validation | L1: Total | M1: Order_Total_After_Discount | N1: Discount Code | O1: Disc % | P1: Discount_Amount | Q1: Payment | R1: Source | S1: City | T1: State | U1: Warehouse | V1: Delivery Date | W1: Delivery_Date_Validation | X1: Delivery_Time_Validation | Y1: Status | Z1: Return? | AA1: Reason | AB1: Return Received | AC1: Return_Date_Validation | AD1: Return_Window_Validation | AE1: Refund
A2: UT-100004 | B2: 45566 | C2: Valid Q4 | D2: CUST_10004 | E2: New | F2: OUT-JKT-XL | G2: Outerwear | H2: Denim Jacket | I2: 3499 | J2: 1 | K2: Valid Quantity | L2: 3499 | M2: 2974.15 | N2: FIRST15 | O2: 15 | P2: 524.85 | Q2: Debit Card | R2: Instagram Shop | S2: Chennai | T2: Tamil Nadu | U2: Mumbai | V2: 45573 | W2: Valid Date | X2: On time delivery | Y2: Delivered | Z2: Yes | AA2: Quality Defect | AB2: 45585 | AC2: Returned | AD2: Valid | AE2: Processed
A3: UT-100006 | B3: 45567 | C3: Valid Q4 | D3: CUST_10005 | E3: Returning | F3: TOP-FRM-S | G3: Tops | H3: Printed Blouse | I3: 1599 | J3: 2 | K3: Valid Quantity | L3: 3198 | M3: 3198 | O3: 0 | P3: 0 | Q3: Credit Card | R3: Mobile App | S3: Hyderabad | T3: Telangana | U3: Bangalore | V3: 45572 | W3: Valid Date | X3: On time delivery | Y3: Delivered | Z3: Yes | AA3: Changed Mind | AB3: 45583 | AC3: Returned | AD3: Valid | AE3: Processed
A4: UT-100007 | B4: 45567 | C4: Valid Q4 | D4: CUST_10006 | E4: New | F4: DRS-CAS-M | G4: Dresses | H4: A-Line Dress | I4: 2199 | J4: 1 | K4: Valid Quantity | L4: 2199 | M4: 1759.2 | N4: DIWALI20 | O4: 20 | P4: 439.8 | Q4: COD | R4: Website | S4: Pune | T4: Maharashtra | U4: Mumbai | W4: Not Delivered | X4: Not delivered | Y4: Cancelled | Z4: No | AC4: Not Delivered | AD4: Not returned | AE4: Not Applicable
A5: UT-100008 | B5: 45567 | C5: Valid Q4 | D5: CUST_10007 | E5: New | F5: BOT-TRS-L | G5: Bottoms | H5: Formal Trousers | I5: 2299 | J5: 1 | K5: Valid Quantity | L5: 2299 | M5: 2299 | O5: 0 | P5: 0 | Q5: UPI | R5: Mobile App | S5: Kolkata | T5: West Bengal | U5: Delhi | V5: 45575 | W5: Valid Date | X5: On time delivery | Y5: Delivered | Z5: No | AC5: Not Returned | AD5: Not returned | AE5: Not Applicable
A6: UT-100009 | B6: 45567 | C6: Valid Q4 | D6: CUST_10008 | E6: Returning | F6: TOP-CAS-XL | G6: Tops | H6: Oversized Tee | I6: 1399 | J6: 5 | K6: Valid Quantity | L6: 6995 | M6: 6995 | O6: 0 | P6: 0 | Q6: Credit Card | R6: Website | S6: Ahmedabad | T6: Gujarat | U6: Mumbai | V6: 45574 | W6: Valid Date | X6: On time delivery | Y6: Delivered | Z6: Yes | AA6: Size Issue | AB6: 45587 | AC6: Returned | AD6: Valid | AE6: Processed
A7: UT-100011 | B7: 45568 | C7: Valid Q4 | D7: CUST_10010 | E7: New | F7: ACC-BAG-OS | G7: Accessories | H7: Tote Bag | I7: 1299 | J7: 2 | K7: Valid Quantity | L7: 2598 | M7: 2338.2 | N7: FLAT10 | O7: 10 | P7: 259.8 | Q7: Wallet | R7: Website | S7: Lucknow | T7: Uttar Pradesh | U7: Delhi | V7: 45575 | W7: Valid Date | X7: On time delivery | Y7: Delivered | Z7: No | AC7: Not Returned | AD7: Not returned | AE7: Not Applicable
A8: UT-100012 | B8: 45568 | C8: Valid Q4 | D8: CUST_10011 | E8: New | F8: DRS-PRT-S | G8: Dresses | H8: Party Dress | I8: 3299 | J8: 1 | K8: Valid Quantity | L8: 3299 | M8: 3299 | O8: 0 | P8: 0 | Q8: COD | R8: Mobile App | S8: Chandigarh | T8: Punjab | U8: Delhi | W8: Not Delivered | X8: Not delivered | Y8: RTO | Z8: No | AC8: Not Delivered | AD8: Not returned | AE8: Not Applicable
A9: UT-100013 | B9: 45568 | C9: Valid Q4 | D9: CUST_10012 | E9: Returning | F9: TOP-SLK-M | G9: Tops | H9: Silk Blouse | I9: 2499 | J9: 1 | K9: Valid Quantity | L9: 2499 | M9: 2499 | O9: 0 | P9: 0 | Q9: Credit Card | R9: Website | S9: Mumbai | T9: Maharashtra | U9: Mumbai | V9: 45574 | W9: Valid Date | X9: On time delivery | Y9: Delivered | Z9: No | AC9: Not Returned | AD9: Not returned | AE9: Not Applicable
A10: UT-100014 | B10: 45568 | C10: Valid Q4 | D10: CUST_10013 | E10: New | F10: BOT-SKT-S | G10: Bottoms | H10: Pleated Skirt | I10: 1799 | J10: 2 | K10: Valid Quantity | L10: 3598 | M10: 2878.4 | N10: DIWALI20 | O10: 20 | P10: 719.6 | Q10: UPI | R10: Instagram Shop | S10: Delhi | T10: Delhi | U10: Delhi | V10: 45576 | W10: Valid Date | X10: On time delivery | Y10: Delivered | Z10: Yes | AA10: Size Issue | AB10: 45593 | AC10: Returned | AD10: Valid | AE10: Processed
A11: UT-100015 | B11: 45568 | C11: Valid Q4 | D11: CUST_10014 | E11: New | F11: OUT-CRD-L | G11: Outerwear | H11: Knit Cardigan | I11: 2799 | J11: 1 | K11: Valid Quantity | L11: 2799 | M11: 2799 | O11: 0 | P11: 0 | Q11: Debit Card | R11: Mobile App | S11: Bangalore | T11: Karnataka | U11: Bangalore | V11: 45577 | W11: Valid Date | X11: On time delivery | Y11: Delivered | Z11: No | AC11: Not Returned | AD11: Not returned | AE11: Not Applicable
A12: UT-100016 | B12: 45569 | C12: Valid Q4 | D12: CUST_10015 | E12: Returning | F12: ACC-JWL-OS | G12: Accessories | H12: Statement Earrings | I12: 599 | J12: 4 | K12: Valid Quantity | L12: 2396 | M12: 2396 | O12: 0 | P12: 0 | Q12: COD | R12: Website | S12: Noida | T12: Uttar Pradesh | U12: Delhi | V12: 45579 | W12: Valid Date | X12: On time delivery | Y12: Delivered | Z12: Yes | AA12: Damaged in Transit | AB12: 45591 | AC12: Returned | AD12: Valid | AE12: Processed
A13: UT-100017 | B13: 45569 | C13: Valid Q4 | D13: CUST_10016 | E13: New | F13: TOP-CRP-XS | G13: Tops | H13: Crop Top | I13: 999 | J13: 1 | K13: Valid Quantity | L13: 999 | M13: 849.15 | N13: FIRST15 | O13: 15 | P13: 149.85 | Q13: UPI | R13: Mobile App | S13: Gurgaon | T13: Haryana | U13: Delhi | V13: 45577 | W13: Valid Date | X13: On time delivery | Y13: Delivered | Z13: No | AC13: Not Returned | AD13: Not returned | AE13: Not Applicable
A14: UT-100018 | B14: 45569 | C14: Valid Q4 | D14: CUST_10017 | E14: New | F14: DRS-MAX-M | G14: Dresses | H14: Maxi Dress | I14: 2899 | J14: 1 | K14: Valid Quantity | L14: 2899 | M14: 2899 | O14: 0 | P14: 0 | Q14: Credit Card | R14: Website | S14: Indore | T14: Madhya Pradesh | U14: Mumbai | V14: 45579 | W14: Valid Date | X14: On time delivery | Y14: Delivered | Z14: No | AC14: Not Returned | AD14: Not returned | AE14: Not Applicable
A15: UT-100019 | B15: 45569 | C15: Valid Q4 | D15: CUST_10018 | E15: Returning | F15: BOT-JGR-M | G15: Bottoms | H15: Joggers | I15: 1499 | J15: 2 | K15: Valid Quantity | L15: 2998 | M15: 2998 | O15: 0 | P15: 0 | Q15: Wallet | R15: Instagram Shop | S15: Surat | T15: Gujarat | U15: Mumbai | V15: 45578 | W15: Valid Date | X15: On time delivery | Y15: Delivered | Z15: Yes | AA15: Size Issue | AB15: 45595 | AC15: Returned | AD15: Valid | AE15: Processed
A16: UT-100020 | B16: 45570 | C16: Valid Q4 | D16: CUST_10019 | E16: New | F16: OUT-VST-S | G16: Outerwear | H16: Puffer Vest | I16: 3999 | J16: 1 | K16: Valid Quantity | L16: 3999 | M16: 3199.2 | N16: DIWALI20 | O16: 20 | P16: 799.8 | Q16: COD | R16: Website | S16: Patna | T16: Bihar | U16: Delhi | W16: Not Delivered | X16: Not delivered | Y16: RTO | Z16: No | AC16: Not Delivered | AD16: Not returned | AE16: Not Applicable
A17: UT-100021 | B17: 45570 | C17: Valid Q4 | D17: CUST_10020 | E17: New | F17: TOP-TUN-L | G17: Tops | H17: Tunic Top | I17: 1699 | J17: 1 | K17: Valid Quantity | L17: 1699 | M17: 1699 | O17: 0 | P17: 0 | Q17: UPI | R17: Mobile App | S17: Bhopal | T17: Madhya Pradesh | U17: Mumbai | V17: 45580 | W17: Valid Date | X17: On time delivery | Y17: Delivered | Z17: No | AC17: Not Returned | AD17: Not returned | AE17: Not Applicable
A18: UT-100022 | B18: 45570 | C18: Valid Q4 | D18: CUST_10021 | E18: Returning | F18: DRS-SHT-XS | G18: Dresses | H18: Shirt Dress | I18: 2399 | J18: 1 | K18: Valid Quantity | L18: 2399 | M18: 2399 | O18: 0 | P18: 0 | Q18: Credit Card | R18: Website | S18: Nagpur | T18: Maharashtra | U18: Mumbai | V18: 45581 | W18: Valid Date | X18: On time delivery | Y18: Delivered | Z18: Yes | AA18: Quality Defect | AB18: 45598 | AC18: Returned | AD18: Valid | AE18: Processed
A19: UT-100023 | B19: 45570 | C19: Valid Q4 | D19: CUST_10022 | E19: New | F19: ACC-BLT-M | G19: Accessories | H19: Leather Belt | I19: 899 | J19: 1 | K19: Valid Quantity | L19: 899 | M19: 809.1 | N19: FLAT10 | O19: 10 | P19: 89.9 | Q19: Debit Card | R19: Mobile App | S19: Coimbatore | T19: Tamil Nadu | U19: Bangalore | V19: 45582 | W19: Valid Date | X19: On time delivery | Y19: Delivered | Z19: No | AC19: Not Returned | AD19: Not returned | AE19: Not Applicable
A20: UT-100024 | B20: 45571 | C20: Valid Q4 | D20: CUST_10023 | E20: New | F20: BOT-SHT-M | G20: Bottoms | H20: Cotton Shorts | I20: 1199 | J20: 3 | K20: Valid Quantity | L20: 3597 | M20: 3597 | O20: 0 | P20: 0 | Q20: COD | R20: Instagram Shop | S20: Kochi | T20: Kerala | U20: Bangalore | V20: 45583 | W20: Valid Date | X20: On time delivery | Y20: Delivered | Z20: Yes | AA20: Changed Mind | AB20: 45601 | AC20: Returned | AD20: Valid | AE20: Processed
A21: UT-100025 | B21: 45571 | C21: Valid Q4 | D21: CUST_10024 | E21: New | F21: TOP-PLO-L | G21: Tops | H21: Polo Shirt | I21: 1799 | J21: 2 | K21: Valid Quantity | L21: 3598 | M21: 3598 | O21: 0 | P21: 0 | Q21: UPI | R21: Website | S21: Vizag | T21: Andhra Pradesh | U21: Bangalore | V21: 45582 | W21: Valid Date | X21: On time delivery | Y21: Delivered | Z21: No | AC21: Not Returned | AD21: Not returned | AE21: Not Applicable
A22: UT-100026 | B22: 45571 | C22: Valid Q4 | D22: CUST_10025 | E22: New | F22: DRS-WRK-M | G22: Dresses | H22: Work Dress | I22: 2699 | J22: 1 | K22: Valid Quantity | L22: 2699 | M22: 2699 | O22: 0 | P22: 0 | Q22: Credit Card | R22: Mobile App | S22: Thiruvananthapuram | T22: Kerala | U22: Bangalore | V22: 45583 | W22: Valid Date | X22: On time delivery | Y22: Delivered | Z22: No | AC22: Not Returned | AD22: Not returned | AE22: Not Applicable
A23: UT-100027 | B23: 45571 | C23: Valid Q4 | D23: CUST_10026 | E23: Returning | F23: OUT-TRN-L | G23: Outerwear | H23: Trench Coat | I23: 4599 | J23: 1 | K23: Valid Quantity | L23: 4599 | M23: 4139.1 | N23: FLAT10 | O23: 10 | P23: 459.9 | Q23: Debit Card | R23: Website | S23: Mysore | T23: Karnataka | U23: Bangalore | V23: 45584 | W23: Valid Date | X23: On time delivery | Y23: Delivered | Z23: Yes | AA23: Size Issue | AB23: 45604 | AC23: Returned | AD23: Valid | AE23: Processed
A24: UT-100028 | B24: 45572 | C24: Valid Q4 | D24: CUST_10027 | E24: New | F24: ACC-HAT-OS | G24: Accessories | H24: Fedora Hat | I24: 1099 | J24: 1 | K24: Valid Quantity | L24: 1099 | M24: 1099 | O24: 0 | P24: 0 | Q24: UPI | R24: Instagram Shop | S24: Vadodara | T24: Gujarat | U24: Mumbai | V24: 45585 | W24: Valid Date | X24: On time delivery | Y24: Delivered | Z24: No | AC24: Not Returned | AD24: Not returned | AE24: Not Applicable
A25: UT-100029 | B25: 45572 | C25: Valid Q4 | D25: CUST_10028 | E25: New | F25: TOP-DNM-M | G25: Tops | H25: Denim Shirt | I25: 1899 | J25: 1 | K25: Valid Quantity | L25: 1899 | M25: 1899 | O25: 0 | P25: 0 | Q25: COD | R25: Mobile App | S25: Rajkot | T25: Gujarat | U25: Mumbai | W25: Not Delivered | X25: Not delivered | Y25: RTO | Z25: No | AC25: Not Delivered | AD25: Not returned | AE25: Not Applicable
A26: UT-100030 | B26: 45572 | C26: Valid Q4 | D26: CUST_10029 | E26: New | F26: BOT-CRG-L | G26: Bottoms | H26: Cargo Pants | I26: 2199 | J26: 1 | K26: Valid Quantity | L26: 2199 | M26: 1759.2 | N26: DIWALI20 | O26: 20 | P26: 439.8 | Q26: Credit Card | R26: Website | S26: Kanpur | T26: Uttar Pradesh | U26: Delhi | V26: 45585 | W26: Valid Date | X26: On time delivery | Y26: Delivered | Z26: No | AC26: Not Returned | AD26: Not returned | AE26: Not Applicable
A27: UT-100031 | B27: 45572 | C27: Valid Q4 | D27: CUST_10030 | E27: Returning | F27: DRS-EVE-S | G27: Dresses | H27: Evening Gown | I27: 5499 | J27: 1 | K27: Valid Quantity | L27: 5499 | M27: 5499 | O27: 0 | P27: 0 | Q27: Credit Card | R27: Mobile App | S27: Mumbai | T27: Maharashtra | U27: Mumbai | V27: 45586 | W27: Valid Date | X27: On time delivery | Y27: Delivered | Z27: Yes | AA27: Size Issue | AB27: 45606 | AC27: Returned | AD27: Valid | AE27: Processed
A28: UT-100032 | B28: 45573 | C28: Valid Q4 | D28: CUST_10031 | E28: New | F28: TOP-BAS-M | G28: Tops | H28: Basic Tank | I28: 899 | J28: 2 | K28: Valid Quantity | L28: 1798 | M28: 1798 | O28: 0 | P28: 0 | Q28: UPI | R28: Website | S28: Delhi | T28: Delhi | U28: Delhi | V28: 45579 | W28: Valid Date | X28: On time delivery | Y28: Delivered | Z28: No | AC28: Not Returned | AD28: Not returned | AE28: Not Applicable
A29: UT-100033 | B29: 45573 | C29: Valid Q4 | D29: CUST_10032 | E29: New | F29: OUT-WOL-L | G29: Outerwear | H29: Wool Coat | I29: 6999 | J29: 1 | K29: Valid Quantity | L29: 6999 | M29: 5949.15 | N29: FIRST15 | O29: 15 | P29: 1049.85 | Q29: Debit Card | R29: Instagram Shop | S29: Kolkata | T29: West Bengal | U29: Delhi | V29: 45581 | W29: Valid Date | X29: On time delivery | Y29: Delivered | Z29: Yes | AA29: Quality Defect | AB29: 45601 | AC29: Returned | AD29: Valid | AE29: Processed
A30: UT-100034 | B30: 45573 | C30: Valid Q4 | D30: CUST_10033 | E30: Returning | F30: ACC-WCH-OS | G30: Accessories | H30: Fashion Watch | I30: 2999 | J30: 1 | K30: Valid Quantity | L30: 2999 | M30: 2999 | O30: 0 | P30: 0 | Q30: Credit Card | R30: Mobile App | S30: Chennai | T30: Tamil Nadu | U30: Bangalore | V30: 45580 | W30: Valid Date | X30: On time delivery | Y30: Delivered | Z30: No | AC30: Not Returned | AD30: Not returned | AE30: Not Applicable
A31: UT-100035 | B31: 45573 | C31: Valid Q4 | D31: CUST_10034 | E31: New | F31: BOT-DNM-S | G31: Bottoms | H31: Denim Shorts | I31: 1599 | J31: 1 | K31: Valid Quantity | L31: 1599 | M31: 1599 | O31: 0 | P31: 0 | Q31: COD | R31: Website | S31: Hyderabad | T31: Telangana | U31: Bangalore | V31: 45582 | W31: Valid Date | X31: On time delivery | Y31: Delivered | Z31: Yes | AA31: Size Issue | AB31: 45604 | AC31: Returned | AD31: Valid | AE31: Processed
A32: UT-100036 | B32: 45574 | C32: Valid Q4 | D32: CUST_10035 | E32: New | F32: DRS-SUN-M | G32: Dresses | H32: Sundress | I32: 1999 | J32: 1 | K32: Valid Quantity | L32: 1999 | M32: 1599.2 | N32: DIWALI20 | O32: 20 | P32: 399.8 | Q32: Wallet | R32: Mobile App | S32: Pune | T32: Maharashtra | U32: Mumbai | V32: 45581 | W32: Valid Date | X32: On time delivery | Y32: Delivered | Z32: No | AC32: Not Returned | AD32: Not returned | AE32: Not Applicable
A33: UT-100037 | B33: 45574 | C33: Valid Q4 | D33: CUST_10036 | E33: New | F33: TOP-RFL-S | G33: Tops | H33: Ruffle Top | I33: 1799 | J33: 1 | K33: Valid Quantity | L33: 1799 | M33: 1799 | O33: 0 | P33: 0 | Q33: UPI | R33: Instagram Shop | S33: Ahmedabad | T33: Gujarat | U33: Mumbai | V33: 45582 | W33: Valid Date | X33: On time delivery | Y33: Delivered | Z33: Yes | AA33: Changed Mind | AB33: 45608 | AC33: Returned | AD33: Valid | AE33: Processed
A34: UT-100038 | B34: 45574 | C34: Valid Q4 | D34: CUST_10037 | E34: Returning | F34: OUT-LTH-M | G34: Outerwear | H34: Leather Jacket | I34: 7999 | J34: 1 | K34: Valid Quantity | L34: 7999 | M34: 7999 | O34: 0 | P34: 0 | Q34: Credit Card | R34: Website | S34: Jaipur | T34: Rajasthan | U34: Delhi | V34: 45583 | W34: Valid Date | X34: On time delivery | Y34: Delivered | Z34: No | AC34: Not Returned | AD34: Not returned | AE34: Not Applicable
A35: UT-100039 | B35: 45574 | C35: Valid Q4 | D35: CUST_10038 | E35: New | F35: ACC-SNG-OS | G35: Accessories | H35: Sunglasses | I35: 1499 | J35: 1 | K35: Valid Quantity | L35: 1499 | M35: 1349.1 | N35: FLAT10 | O35: 10 | P35: 149.9 | Q35: Debit Card | R35: Mobile App | S35: Lucknow | T35: Uttar Pradesh | U35: Delhi | V35: 45582 | W35: Valid Date | X35: On time delivery | Y35: Delivered | Z35: No | AC35: Not Returned | AD35: Not returned | AE35: Not Applicable
A36: UT-100040 | B36: 45575 | C36: Valid Q4 | D36: CUST_10039 | E36: New | F36: BOT-PLZ-L | G36: Bottoms | H36: Palazzo Pants | I36: 1699 | J36: 1 | K36: Valid Quantity | L36: 1699 | M36: 1699 | O36: 0 | P36: 0 | Q36: COD | R36: Website | S36: Bangalore | T36: Karnataka | U36: Bangalore | V36: 45584 | W36: Valid Date | X36: On time delivery | Y36: Delivered | Z36: Yes | AA36: Size Issue | AB36: 45606 | AC36: Returned | AD36: Valid | AE36: Processed
A37: UT-100041 | B37: 45575 | C37: Valid Q4 | D37: CUST_10040 | E37: New | F37: DRS-BDC-S | G37: Dresses | H37: Bodycon Dress | I37: 2299 | J37: 1 | K37: Valid Quantity | L37: 2299 | M37: 2299 | O37: 0 | P37: 0 | Q37: UPI | R37: Instagram Shop | S37: Mumbai | T37: Maharashtra | U37: Mumbai | V37: 45583 | W37: Valid Date | X37: On time delivery | Y37: Delivered | Z37: No | AC37: Not Returned | AD37: Not returned | AE37: Not Applicable
A38: UT-100042 | B38: 45575 | C38: Valid Q4 | D38: CUST_10041 | E38: Returning | F38: TOP-OFF-M | G38: Tops | H38: Off-Shoulder Top | I38: 1599 | J38: 2 | K38: Valid Quantity | L38: 3198 | M38: 2558.4 | N38: DIWALI20 | O38: 20 | P38: 639.6 | Q38: Credit Card | R38: Mobile App | S38: Delhi | T38: Delhi | U38: Delhi | V38: 45582 | W38: Valid Date | X38: On time delivery | Y38: Delivered | Z38: Yes | AA38: Wrong Item | AB38: 45604 | AC38: Returned | AD38: Valid | AE38: Processed
A39: UT-100043 | B39: 45575 | C39: Valid Q4 | D39: CUST_10042 | E39: New | F39: OUT-DNM-L | G39: Outerwear | H39: Denim Vest | I39: 2499 | J39: 1 | K39: Valid Quantity | L39: 2499 | M39: 2499 | O39: 0 | P39: 0 | Q39: Wallet | R39: Website | S39: Chandigarh | T39: Punjab | U39: Delhi | V39: 45585 | W39: Valid Date | X39: On time delivery | Y39: Delivered | Z39: No | AC39: Not Returned | AD39: Not returned | AE39: Not Applicable
A40: UT-100044 | B40: 45576 | C40: Valid Q4 | D40: CUST_10043 | E40: New | F40: ACC-HBG-OS | G40: Accessories | H40: Hobo Bag | I40: 1899 | J40: 1 | K40: Valid Quantity | L40: 1899 | M40: 1899 | O40: 0 | P40: 0 | Q40: Debit Card | R40: Instagram Shop | S40: Noida | T40: Uttar Pradesh | U40: Delhi | V40: 45586 | W40: Valid Date | X40: On time delivery | Y40: Delivered | Z40: Yes | AA40: Damaged in Transit | AB40: 45608 | AC40: Returned | AD40: Valid | AE40: Processed
...

Sheet Note
M1: Column | N1: Description
M2: discount_code | N2: Promo code applied; blank if no discount
M3: delivery_date | N3: Actual delivery date (blank if not delivered or cancelled)
M13: SKU - Stock keeping unit
M14: Totla_order - unit_price × quantity
M15: AOV - Average Order Value
M16: RTO - Return To Origin

Sheet Q4_Summary_Dashboard
C4: Row Labels | D4: Total Order | E4: Totla Revenue (After discount) | F4: Total Units Sold | H4: AOV (avergae order value) | I4: Overall Return Rate %
C5: 01-10-2024 - 07-10-2024 | D5: 26 | E5: 72576.7 | F5: 40 | H5: =GETPIVOTDATA("Totla Revenue (After discount)",Q4_Summary_Dashboard!$C$4)/GETPIVOTDATA("Total Order",Q4_Summary_Dashboard!$C$4) -> 2626.0087 | I5: =(I14/I15)*100 -> 55.140187
C6: 08-10-2024 - 14-10-2024 | D6: 29 | E6: 73463.65 | F6: 33
C7: 15-10-2024 - 21-10-2024 | D7: 28 | E7: 57126.6 | F7: 35
C8: 22-10-2024 - 28-10-2024 | D8: 28 | E8: 61419.8 | F8: 34
C9: 29-10-2024 - 04-11-2024 | D9: 31 | E9: 71500.2 | F9: 33
C10: 05-11-2024 - 11-11-2024 | D10: 21 | E10: 46956.55 | F10: 27
C11: 12-11-2024 - 18-11-2024 | D11: 21 | E11: 62884.05 | F11: 22
C12: 19-11-2024 - 25-11-2024 | D12: 21 | E12: 57673.75 | F12: 22
C13: 26-11-2024 - 02-12-2024 | D13: 23 | E13: 64174.65 | F13: 27 | H13: AOV= sum(total revenue)/count(total order)
C14: 03-12-2024 - 09-12-2024 | D14: 27 | E14: 78752.6 | F14: 30 | H14: Return Initiated = | I14: =COUNTIFS(Cleaned_Data!Z:Z,"Yes") -> 177
C15: 10-12-2024 - 16-12-2024 | D15: 29 | E15: 86449.2 | F15: 33 | H15: Delivered Orders = | I15: =COUNTIF(Cleaned_Data!Y:Y,"Delivered") -> 321
C16: 17-12-2024 - 23-12-2024 | D16: 28 | E16: 82070 | F16: 32
C17: 24-12-2024 - 30-12-2024 | D17: 26 | E17: 71570 | F17: 32
C18: 31-12-2024 - 01-01-2025 | D18: 1 | E18: 3599.2 | F18: 1
C19: 45657 | D19: 1 | E19: 3599.2 | F19: 1
C20: Grand Total | D20: 339 | E20: 890216.95 | F20: 401

Sheet Trend Analysis
A1: Row Labels | B1: Order Volume | C1: Return Rate | D1: Average Discount %
A2: 01-10-2024 - 07-10-2024 | B2: 26 | C2: 10 | D2: 5.3846154
A3: 08-10-2024 - 14-10-2024 | B3: 29 | C3: 12 | D3: 5
A4: 15-10-2024 - 21-10-2024 | B4: 28 | C4: 12 | D4: 5.3571429
A5: 22-10-2024 - 28-10-2024 | B5: 28 | C5: 12 | D5: 11.785714
A6: 29-10-2024 - 04-11-2024 | B6: 31 | C6: 23 | D6: 40
A7: 05-11-2024 - 11-11-2024 | B7: 21 | C7: 11 | D7: 11.190476
A8: 12-11-2024 - 18-11-2024 | B8: 21 | C8: 12 | D8: 4.2857143
A9: 19-11-2024 - 25-11-2024 | B9: 21 | C9: 11 | D9: 3.5714286
A10: 26-11-2024 - 02-12-2024 | B10: 23 | C10: 12 | D10: 6.3043478
A11: 03-12-2024 - 09-12-2024 | B11: 27 | C11: 12 | D11: 8.1481481
A12: 10-12-2024 - 16-12-2024 | B12: 29 | C12: 16 | D12: 6.8965517
A13: 17-12-2024 - 23-12-2024 | B13: 28 | C13: 17 | D13: 6.4285714
... A16: Grand Total | B16: 339 | C16: 177 | D16: 9.8230088

Sheet Segment Analysis
A1: Row Labels | B1: Order Volume | C1: Average Order Value | D1: Return Count | E1: Return Rate
A2: New | B2: 264 | C2: 2599.9544 | D2: 145 | E2: =GETPIVOTDATA("Return Count",$A$1,"Type","New")/GETPIVOTDATA("Order Volume",$A$1,"Type","New")*100 -> 54.924242
A3: Returning | B3: 75 | C3: 2717.72 | D3: 32 | E3: =GETPIVOTDATA("Return Count",$A$1,"Type","Returning")/GETPIVOTDATA("Order Volume",$A$1,"Type","Returning")*100 -> 42.666667
A4: Grand Total | B4: 339 | C4: 2626.0087 | D4: 177
A7: Row Labels | B7: Count of Order ID | C7: Average of Order_Total_After_Discount | D7: Count of Return Received | E7: Return Rate
A8: Instagram Shop | B8: 108 | C8: 2757.1625 | D8: 70 | E8: =GETPIVOTDATA("Count of Return Received",$A$7,"Source","Instagram Shop")/GETPIVOTDATA("Count of Order ID",$A$7,"Source","Instagram Shop")*100 -> 64.814815
A9: Mobile App | B9: 114 | C9: 2552.3408 | D9: 59 | E9: =GETPIVOTDATA("Count of Return Received",$A$7,"Source","Mobile App")/GETPIVOTDATA("Count of Order ID",$A$7,"Source","Mobile App")*100 -> 51.754386
A10: Website | B10: 117 | C10: 2576.7226 | D10: 48 | E10: =GETPIVOTDATA("Count of Return Received",$A$7,"Source","Website")/GETPIVOTDATA("Count of Order ID",$A$7,"Source","Website")*100 -> 41.025641
A11: Grand Total | B11: 339 | C11: 2626.0087 | D11: 177
A14: Row Labels | B14: Count of Order ID | C14: Average of Order_Total_After_Discount | D14: Count of Return Received | E14: Return Rate
A15: COD | B15: 62 | C15: 3033.2798 | D15: 38 | E15: =GETPIVOTDATA("Count of Return Received",$A$14,"Payment","COD")/GETPIVOTDATA("Count of Order ID",$A$14,"Payment","COD")*100 -> 61.290323
A16: Credit Card | B16: 86 | C16: 3107.2041 | D16: 46 | E16: =GETPIVOTDATA("Count of Return Received",$A$14,"Payment","Credit Card")/GETPIVOTDATA("Count of Order ID",$A$14,"Payment","Credit Card")*100 -> 53.488372
A17: Debit Card | B17: 59 | C17: 2473.3483 | D17: 42 | E17: =GETPIVOTDATA("Count of Return Received",$A$14,"Payment","Debit Card")/GETPIVOTDATA("Count of Order ID",$A$14,"Payment","Debit Card")*100 -> 71.186441
A18: UPI | B18: 80 | C18: 2327.78 | D18: 35 | E18: =GETPIVOTDATA("Count of Return Received",$A$14,"Payment","UPI")/GETPIVOTDATA("Count of Order ID",$A$14,"Payment","UPI")*100 -> 43.75
A19: Wallet | B19: 52 | C19: 1976.6173 | D19: 16 | E19: =GETPIVOTDATA("Count of Return Received",$A$14,"Payment","Wallet")/GETPIVOTDATA("Count of Order ID",$A$14,"Payment","Wallet")*100 -> 30.769231
A20: Grand Total | B20: 339 | C20: 2626.0087 | D20: 177
A23: Row Labels | B23: Count of Order ID | C23: Average of Order_Total_After_Discount | D23: Count of Return Received | E23: Return Rate
A24: Accessories | B24: 67 | C24: 1275.8328 | D24: 16 | E24: =GETPIVOTDATA("Count of Return Received",$A$23,"Category","Accessories")/GETPIVOTDATA("Count of Order ID",$A$23,"Category","Accessories")*100 -> 23.880597
A25: Bottoms | B25: 66 | C25: 2073.1129 | D25: 25 | E25: =GETPIVOTDATA("Count of Return Received",$A$23,"Category","Bottoms")/GETPIVOTDATA("Count of Order ID",$A$23,"Category","Bottoms")*100 -> 37.878788
A26: Dresses | B26: 68 | C26: 3144.4037 | D26: 42 | E26: =GETPIVOTDATA("Count of Return Received",$A$23,"Category","Dresses")/GETPIVOTDATA("Count of Order ID",$A$23,"Category","Dresses")*100 -> 61.764706
A27: Outerwear | B27: 67 | C27: 4682.6918 | D27: 51 | E27: =GETPIVOTDATA("Count of Return Received",$A$23,"Category","Outerwear")/GETPIVOTDATA("Count of Order ID",$A$23,"Category","Outerwear")*100 -> 76.119403
A28: Tops | B28: 71 | C28: 1976.7732 | D28: 43 | E28: =GETPIVOTDATA("Count of Return Received",$A$23,"Category","Tops")/GETPIVOTDATA("Count of Order ID",$A$23,"Category","Tops")*100 -> 60.56338
A29: Grand Total | B29: 339 | C29: 2626.0087 | D29: 177

Sheet KPI Metrics
C3: GMV= | D3: =SUM(Table1_12[Total]) -> 1003499 | H3: count(RTO)= | I3: =COUNTIF(Table1_12[Status],"rto") -> 17
C4: Net revenue= | D4: =SUM(Table1_12[Order_Total_After_Discount]) -> 890216.95 | H4: count(Delivery date)= | I4: =COUNT(Table1_12[Delivery Date]) -> 321
C5: Return Rate= | D5: =(COUNT(Table1_12[Return Received])/(COUNT(Table1_12[Delivery Date])))*100 -> 55.140187
C6: RTO Rate= | D6: =I3/I4*100 -> 5.2959502
C7: Refund Processing Rate = | D7: =COUNTIF(Table1_12[Refund],"processed")/COUNT(Cleaned_Data!AB:AB)*100 -> 96.610169 | H7: Row Labels | I7: Order Volume | J7: Average Order Value | K7: Return Count
C8: First Time Buyer Return Rate = | D8: =GETPIVOTDATA("Return Count",$H$7,"Type","New")/GETPIVOTDATA("Order Volume",$H$7,"Type","New")*100 -> 54.924242 | H8: New | I8: 264 | J8: 2599.9544 | K8: 145
C9: Returning Time Buyer Return Rate = | D9: =GETPIVOTDATA("Return Count",$H$7,"Type","Returning")/GETPIVOTDATA("Order Volume",$H$7,"Type","Returning")*100 -> 42.666667 | H9: Returning | I9: 75 | J9: 2717.72 | K9: 32
C10: Bangalore fullfillment = | D10: =I12/I15*100 -> 27.138643 | H10: Grand Total | I10: 339 | J10: 2626.0087 | K10: 177
C11: Delhi fullfillment= | D11: =I13/I15*100 -> 37.758112
C12: Mumbai fullfillment= | D12: =I14/I15*100 -> 35.103245 | H12: Bangalore warehouse = | I12: =COUNTIF(Cleaned_Data!U:U,"bangalore") -> 92
H13: delhi warehouse = | I13: =COUNTIF(Cleaned_Data!U:U,"delhi") -> 128
H14: mumbai warehouse = | I14: =COUNTIF(Cleaned_Data!U:U,"mumbai") -> 119
I15: =SUM(I12:I14) -> 339

Sheet Business Interpretation

Sheet Cleaning_Log

Sheet Validation Summary

Sheet Analysis
